<?xml version="1.0" ?>
<sdf version='1.8' xmlns:gz="https://gazebosim.org/schema/gz">
  <model name='nexus_4wd_mecanum_scaled5x'>
    <link name='base_footprint'>
      <inertial>
        <pose>-0.05119014360313315 -1.4154075358818594e-18 0.25928198433420323 0 0 0</pose>
        <mass>383.0000000000001</mass>
        <inertia>
          <ixx>68.9798016144395</ixx>
          <ixy>2.777 * 10^-17</ixy>
          <ixz>-0.30317520938475625</ixz>
          <iyy>194.8410000000001</iyy>
          <iyz>-7.441 * 10^-16</iyz>
          <izz>257.6286288881078</izz>
        </inertia>
      </inertial>

      <!-- Collisions & Visuals for base and sensors -->
      <collision name='base_link_collision'>
        <pose>0 0 0.25 0 0 0</pose>
        <geometry>
          <mesh>
            <scale>0.005 0.005 0.005</scale>
            <uri>model://meshes/nexus_4wd_mecanum/meshes/nexus_base_link_collision.STL</uri>
          </mesh>
        </geometry>
        <surface>
          <contact><ode/></contact>
          <friction><ode/></friction>
        </surface>
      </collision>
      <visual name='base_link_visual'>
        <pose>0 0 0.25 0 0 0</pose>
        <geometry>
          <mesh>
            <scale>0.005 0.005 0.005</scale>
            <uri>model://meshes/nexus_4wd_mecanum/meshes/nexus_base_link.STL</uri>
          </mesh>
        </geometry>
        <material>
          <script>
            <name>Gazebo/Yellow</name>
            <uri>file://media/materials/scripts/gazebo.material</uri>
          </script>
          <diffuse>1 1 0 1</diffuse>
          <ambient>1 1 0 1</ambient>
        </material>
      </visual>

      <!-- Sensor visuals -->
      <visual name='front_sensor_visual'>
        <pose>1.0249999999999999 0 0.29999999999999999 1.57079632679 0 0</pose>
        <geometry>
          <mesh>
            <scale>0.005 0.005 0.005</scale>
            <uri>model://meshes/nexus_4wd_mecanum/meshes/urm04.STL</uri>
          </mesh>
        </geometry>
        <material>
          <script>
            <name>Gazebo/Black</name>
            <uri>file://media/materials/scripts/gazebo.material</uri>
          </script>
          <diffuse>0.187500015 0.187500015 0.187500015 1</diffuse>
          <ambient>0.187500015 0.187500015 0.187500015 1</ambient>
        </material>
      </visual>
      <visual name='left_sensor_visual'>
        <pose>0 0.54 0.29999999999999999 1.57079632679 -5.5511151231257827e-17 1.57079632679</pose>
        <geometry>
          <mesh>
            <scale>0.005 0.005 0.005</scale>
            <uri>model://meshes/nexus_4wd_mecanum/meshes/urm04.STL</uri>
          </mesh>
        </geometry>
        <material>
          <script>
            <name>Gazebo/Black</name>
            <uri>file://media/materials/scripts/gazebo.material</uri>
          </script>
          <diffuse>0.187500015 0.187500015 0.187500015 1</diffuse>
          <ambient>0.187500015 0.187500015 0.187500015 1</ambient>
        </material>
      </visual>
      <visual name='right_sensor_visual'>
        <pose>0 -0.54 0.29999999999999999 1.57079632679 5.5511151231257827e-17 -1.57079632679</pose>
        <geometry>
          <mesh>
            <scale>0.005 0.005 0.005</scale>
            <uri>model://meshes/nexus_4wd_mecanum/meshes/urm04.STL</uri>
          </mesh>
        </geometry>
        <material>
          <script>
            <name>Gazebo/Black</name>
            <uri>file://media/materials/scripts/gazebo.material</uri>
          </script>
          <diffuse>0.187500015 0.187500015 0.187500015 1</diffuse>
          <ambient>0.187500015 0.187500015 0.187500015 1</ambient>
        </material>
      </visual>
      <visual name='rear_sensor_visual'>
        <pose>-1.0050000000000001 0 0.29999999999999999 1.57079632679 0 -3.1415926535895871</pose>
        <geometry>
          <mesh>
            <scale>0.005 0.005 0.005</scale>
            <uri>model://meshes/nexus_4wd_mecanum/meshes/urm04.STL</uri>
          </mesh>
        </geometry>
        <material>
          <script>
            <name>Gazebo/Black</name>
            <uri>file://media/materials/scripts/gazebo.material</uri>
          </script>
          <diffuse>0.187500015 0.187500015 0.187500015 1</diffuse>
          <ambient>0.187500015 0.187500015 0.187500015 1</ambient>
        </material>
      </visual>

      <gravity>true</gravity>
      
      <!-- Sensors -->
      <sensor name='front_sensor' type='ray'>
        <always_on>true</always_on>
        <update_rate>10</update_rate>
        <visualize>true</visualize>
        <ray>
          <scan>
            <horizontal>
              <samples>2</samples>
              <resolution>1</resolution>
              <min_angle>-0.52</min_angle>
              <max_angle>0.52</max_angle>
            </horizontal>
            <vertical>
              <samples>2</samples>
              <resolution>1</resolution>
              <min_angle>-0.02</min_angle>
              <max_angle>0.02</max_angle>
            </vertical>
          </scan>
          <range>
            <min>0.04</min>
            <max>2.5</max>
            <resolution>0.01</resolution>
          </range>
        </ray>
        <pose>1.0249999999999999 0 0.29999999999999999 0 0 0</pose>
      </sensor>

      <sensor name='left_sensor' type='ray'>
        <always_on>true</always_on>
        <update_rate>10</update_rate>
        <visualize>true</visualize>
        <ray>
          <scan>
            <horizontal>
              <samples>2</samples>
              <resolution>1</resolution>
              <min_angle>-0.52</min_angle>
              <max_angle>0.52</max_angle>
            </horizontal>
            <vertical>
              <samples>2</samples>
              <resolution>1</resolution>
              <min_angle>-0.02</min_angle>
              <max_angle>0.02</max_angle>
            </vertical>
          </scan>
          <range>
            <min>0.04</min>
            <max>2.5</max>
            <resolution>0.01</resolution>
          </range>
        </ray>
        <pose>0 0.54 0.29999999999999999 0 0 1.5708</pose>
      </sensor>

      <sensor name='right_sensor' type='ray'>
        <always_on>true</always_on>
        <update_rate>10</update_rate>
        <visualize>true</visualize>
        <ray>
          <scan>
            <horizontal>
              <samples>2</samples>
              <resolution>1</resolution>
              <min_angle>-0.52</min_angle>
              <max_angle>0.52</max_angle>
            </horizontal>
            <vertical>
              <samples>2</samples>
              <resolution>1</resolution>
              <min_angle>-0.02</min_angle>
              <max_angle>0.02</max_angle>
            </vertical>
          </scan>
          <range>
            <min>0.04</min>
            <max>2.5</max>
            <resolution>0.01</resolution>
          </range>
        </ray>
        <pose>0 -0.54 0.29999999999999999 0 0 -1.5708</pose>
      </sensor>

      <sensor name='realsense_rgbd' type='camera'>
        <always_on>true</always_on>
        <update_rate>30</update_rate>
        <visualize>true</visualize>
        <pose>1.1 0 0.4 0 0.35 0</pose> 

        <!--     rotations: roll / pitch (+ = down) / yaw (+ = left) -->

        <camera>
          <horizontal_fov>1.047</horizontal_fov> 
          <image>
            <width>640</width>
            <height>480</height>
            <format>R8G8B8</format>
          </image>
          <clip>
            <near>0.05</near>
            <far>10.0</far>
          </clip>
        </camera>

        
      </sensor>

      <sensor name='realsense_depth' type='depth'>
        <always_on>true</always_on>
        <update_rate>30</update_rate>
        <visualize>true</visualize>
        <pose>1.1 0 0.4 0 0 0</pose>

        <camera>
          <horizontal_fov>1.047</horizontal_fov>
          <image>
            <width>640</width>
            <height>480</height>
            <format>L8</format>
          </image>
          <clip>
            <near>0.05</near>
            <far>10.0</far>
          </clip>
        </camera>

      </sensor>

      <sensor name="velodyne_lidar" type="gpu_ray">   <!-- albo `ray`, w zależności od wersji -->
        <pose>0 0 0.3 0 0 0</pose>   <!-- dostosuj wysokość / orientację -->
        <update_rate>10</update_rate>

        <ray>
          <scan>
            <horizontal>
              <samples>1800</samples>       <!-- lub domyślna liczba np. 1875 -->
              <resolution>1</resolution>
              <min_angle>-3.14159</min_angle>
              <max_angle>3.14159</max_angle>
            </horizontal>
            <vertical>
              <samples>16</samples>         <!-- np. dla VLP‑16 -->
              <resolution>1</resolution>
              <min_angle>-0.261799</min_angle>   <!-- ~ –15° -->
              <max_angle>0.261799</max_angle>    <!-- ~ +15° -->
            </vertical>
          </scan>
          <range>
            <min>0.9</min>      <!-- domyślne z velodyne_simulator -->
            <max>130.0</max>
            <resolution>0.01</resolution>
          </range>
          <noise>
            <type>gaussian</type>
            <mean>0.0</mean>
            <stddev>0.008</stddev>    <!-- domyślna wartość z pluginu -->
          </noise>
        </ray>
    </sensor>


      <sensor name='rear_sensor' type='ray'>
        <always_on>true</always_on>
        <update_rate>10</update_rate>
        <visualize>true</visualize>
        <ray>
          <scan>
            <horizontal>
              <samples>2</samples>
              <resolution>1</resolution>
              <min_angle>-0.52</min_angle>
              <max_angle>0.52</max_angle>
            </horizontal>
            <vertical>
              <samples>2</samples>
              <resolution>1</resolution>
              <min_angle>-0.02</min_angle>
              <max_angle>0.02</max_angle>
            </vertical>
          </scan>
          <range>
            <min>0.04</min>
            <max>2.5</max>
            <resolution>0.01</resolution>
          </range>
        </ray>
        <pose>-1.0050000000000001 0 0.29999999999999999 0 0 -3.1415926535895871</pose>
      </sensor>
      
    </link>

    


    <!-- Joints and wheel-links (lower-left, lower-right, upper-left, upper-right) -->
    <joint name='lower_left_wheel_joint' type='revolute'>
      <pose relative_to='base_footprint'>-0.75 0.75 0.25 0 0 0</pose>
      <parent>base_footprint</parent>
      <child>lower_left_wheel</child>
      <axis>
        <xyz>0 1 0</xyz>
        <limit><lower>-inf</lower><upper>inf</upper></limit>
        <dynamics><spring_reference>0</spring_reference><spring_stiffness>0</spring_stiffness></dynamics>
      </axis>
    </joint>
    <link name='lower_left_wheel'>
      <pose relative_to='lower_left_wheel_joint'>0 0 0 0 0 0</pose>
      <inertial>
        <pose>0 0 0 0 0 0</pose>
        <mass>48.050000000000004</mass>
        <inertia>
          <ixx>1.015075</ixx>
          <ixy>0</ixy>
          <ixz>0</ixz>
          <iyy>1.5</iyy>
          <iyz>0</iyz>
          <izz>1.015075</izz>
        </inertia>
      </inertial>
      <collision name='lower_left_wheel_collision'>
        <pose>0 0 0 1.57079632679 0 0</pose>
        <geometry>
          <cylinder>
            <length>0.2525</length>
            <radius>0.25000000000000003</radius>
          </cylinder>
        </geometry>
        <surface>
          <friction>
            <ode>
              <mu>1</mu>
              <mu2>0.05</mu2>
              <fdir1 gz:expressed_in='chassis'>1 -1 0</fdir1>
            </ode>
          </friction>
          <bounce/>
          <contact/>
        </surface>
      </collision>
      <visual name='lower_left_wheel_visual'>
        <pose>0 0 0 0 0 0</pose>
        <geometry>
          <mesh>
            <scale>0.005 0.005 0.005</scale>
            <uri>model://meshes/nexus_4wd_mecanum/meshes/mecanum_wheel_right.STL</uri>
          </mesh>
        </geometry>
        <material>
          <script>
            <name>Gazebo/Grey</name>
            <uri>file://media/materials/scripts/gazebo.material</uri>
          </script>
          <diffuse>0.5 0.5 0.5 1</diffuse>
          <ambient>0.5 0.5 0.5 1</ambient>
        </material>
      </visual>
    </link>

    <joint name='lower_right_wheel_joint' type='revolute'>
      <pose relative_to='base_footprint'>-0.75 -0.75 0.25 -3.1415926535895871 0 0</pose>
      <parent>base_footprint</parent>
      <child>lower_right_wheel</child>
      <axis>
        <xyz>0 1 0</xyz>
        <limit><lower>-inf</lower><upper>inf</upper></limit>
        <dynamics><spring_reference>0</spring_reference><spring_stiffness>0</spring_stiffness></dynamics>
      </axis>
    </joint>
    <link name='lower_right_wheel'>
      <pose relative_to='lower_right_wheel_joint'>0 0 0 0 0 0</pose>
      <inertial>
        <pose>0 0 0 0 0 0</pose>
        <mass>48.050000000000004</mass>
        <inertia>
          <ixx>1.015075</ixx>
          <ixy>0</ixy>
          <ixz>0</ixz>
          <iyy>1.5</iyy>
          <iyz>0</iyz>
          <izz>1.015075</izz>
        </inertia>
      </inertial>
      <collision name='lower_right_wheel_collision'>
        <pose>0 0 0 1.57079632679 0 0</pose>
        <geometry>
          <cylinder>
            <length>0.2525</length>
            <radius>0.25000000000000003</radius>
          </cylinder>
        </geometry>
        <surface>
          <friction>
            <ode>
              <mu>1</mu>
              <mu2>0.05</mu2>
              <fdir1 gz:expressed_in='chassis'>1 -1 0</fdir1>
            </ode>
          </friction>
          <bounce/>
          <contact/>
        </surface>
      </collision>
      <visual name='lower_right_wheel_visual'>
        <pose>0 0 0 0 0 0</pose>
        <geometry>
          <mesh>
            <scale>0.005 0.005 0.005</scale>
            <uri>model://meshes/nexus_4wd_mecanum/meshes/mecanum_wheel_left.STL</uri>
          </mesh>
        </geometry>
        <material>
          <script>
            <name>Gazebo/Grey</name>
            <uri>file://media/materials/scripts/gazebo.material</uri>
          </script>
          <diffuse>0.5 0.5 0.5 1</diffuse>
          <ambient>0.5 0.5 0.5 1</ambient>
        </material>
      </visual>
    </link>

    <joint name='upper_left_wheel_joint' type='revolute'>
      <pose relative_to='base_footprint'>0.75 0.75 0.25 0 0 0</pose>
      <parent>base_footprint</parent>
      <child>upper_left_wheel</child>
      <axis>
        <xyz>0 1 0</xyz>
        <limit><lower>-inf</lower><upper>inf</upper></limit>
        <dynamics><spring_reference>0</spring_reference><spring_stiffness>0</spring_stiffness></dynamics>
      </axis>
    </joint>
    <link name='upper_left_wheel'>
      <pose relative_to='upper_left_wheel_joint'>0 0 0 0 0 0</pose>
      <inertial>
        <pose>0 0 0 0 0 0</pose>
        <mass>48.050000000000004</mass>
        <inertia>
          <ixx>1.015075</ixx>
          <ixy>0</ixy>
          <ixz>0</ixz>
          <iyy>1.5</iyy>
          <iyz>0</iyz>
          <izz>1.015075</izz>
        </inertia>
      </inertial>
      <collision name='upper_left_wheel_collision'>
        <pose>0 0 0 1.57079632679 0 0</pose>
        <geometry>
          <cylinder>
            <length>0.2525</length>
            <radius>0.25000000000000003</radius>
          </cylinder>
        </geometry>
        <surface>
          <friction>
            <ode>
              <mu>1</mu>
              <mu2>0.05</mu2>
              <fdir1 gz:expressed_in='chassis'>1 -1 0</fdir1>
            </ode>
          </friction>
          <bounce/>
          <contact/>
        </surface>
      </collision>
      <visual name='upper_left_wheel_visual'>
        <pose>0 0 0 0 0 0</pose>
        <geometry>
          <mesh>
            <scale>0.005 0.005 0.005</scale>
            <uri>model://meshes/nexus_4wd_mecanum/meshes/mecanum_wheel_left.STL</uri>
          </mesh>
        </geometry>
        <material>
          <script>
            <name>Gazebo/Grey</name>
            <uri>file://media/materials/scripts/gazebo.material</uri>
          </script>
          <diffuse>0.5 0.5 0.5 1</diffuse>
          <ambient>0.5 0.5 0.5 1</ambient>
        </material>
      </visual>
    </link>

    <joint name='upper_right_wheel_joint' type='revolute'>
      <pose relative_to='base_footprint'>0.75 -0.75 0.25 -3.1415926535895871 0 0</pose>
      <parent>base_footprint</parent>
      <child>upper_right_wheel</child>
      <axis>
        <xyz>0 1 0</xyz>
        <limit><lower>-inf</lower><upper>inf</upper></limit>
        <dynamics><spring_reference>0</spring_reference><spring_stiffness>0</spring_stiffness></dynamics>
      </axis>
    </joint>
    <link name='upper_right_wheel'>
      <pose relative_to='upper_right_wheel_joint'>0 0 0 0 0 0</pose>
      <inertial>
        <pose>0 0 0 0 0 0</pose>
        <mass>48.050000000000004</mass>
        <inertia>
          <ixx>1.015075</ixx>
          <ixy>0</ixy>
          <ixz>0</ixz>
          <iyy>1.5</iyy>
          <iyz>0</iyz>
          <izz>1.015075</izz>
        </inertia>
      </inertial>
      <collision name='upper_right_wheel_collision'>
        <pose>0 0 0 1.57079632679 0 0</pose>
        <geometry>
          <cylinder>
            <length>0.2525</length>
            <radius>0.25000000000000003</radius>
          </cylinder>
        </geometry>
        <surface>
          <friction>
            <ode>
              <mu>1</mu>
              <mu2>0.05</mu2>
              <fdir1 gz:expressed_in='chassis'>1 -1 0</fdir1>
            </ode>
          </friction>
          <bounce/>
          <contact/>
        </surface>
      </collision>
      <visual name='upper_right_wheel_visual'>
        <pose>0 0 0 0 0 0</pose>
        <geometry>
          <mesh>
            <scale>0.005 0.005 0.005</scale>
            <uri>model://meshes/nexus_4wd_mecanum/meshes/mecanum_wheel_right.STL</uri>
          </mesh>
        </geometry>
        <material>
          <script>
            <name>Gazebo/Grey</name>
            <uri>file://media/materials/scripts/gazebo.material</uri>
          </script>
          <diffuse>0.5 0 0.5 1</diffuse>
          <ambient>0.5 0.5 0.5 1</ambient>
        </material>
      </visual>
    </link>

    <!-- Plugin with scaled parameters -->
    <plugin name='gz::sim::systems::MecanumDrive' filename='gz-sim-mecanum-drive-system'>
      <front_left_joint>upper_left_wheel_joint</front_left_joint>
      <front_right_joint>upper_right_wheel_joint</front_right_joint>
      <back_left_joint>lower_left_wheel_joint</back_left_joint>
      <back_right_joint>lower_right_wheel_joint</back_right_joint>
      <wheel_separation>6.25</wheel_separation>
      <wheelbase>7.555</wheelbase>
      <wheel_radius>1.5</wheel_radius>
      <min_acceleration>-5</min_acceleration>
      <max_acceleration>5</max_acceleration>
    </plugin>

   

    <plugin name='gz::sim::systems::Sensors' filename='gz-sim-sensors-system'>
      <render_engine>ogre2</render_engine>
    </plugin>


    <!-- Frames (sensor & shafts) attached to base_link and base_footprint -->
    <frame name='front_sensor_joint' attached_to='base_link'>
      <pose>1.0249999999999999 0 0.05 0 0 0</pose>
    </frame>
    <frame name='front_sensor' attached_to='front_sensor_joint'>
      <pose>0 0 0 0 0 0</pose>
    </frame>

    <frame name='left_sensor_joint' attached_to='base_link'>
      <pose>0 0.54 0.05 0 0 1.5708</pose>
    </frame>
    <frame name='left_sensor' attached_to='left_sensor_joint'>
      <pose>0 0 0 0 0 0</pose>
    </frame>

    <frame name='right_sensor_joint' attached_to='base_link'>
      <pose>0 -0.54 0.05 0 0 -1.5708</pose>
    </frame>
    <frame name='right_sensor' attached_to='right_sensor_joint'>
      <pose>0 0 0 0 0 0</pose>
    </frame>

    <frame name='rear_sensor_joint' attached_to='base_link'>
      <pose>-1.0050000000000001 0 0.05 0 0 -3.1415926535895871</pose>
    </frame>
    <frame name='rear_sensor' attached_to='rear_sensor_joint'>
      <pose>0 0 0 0 0 0</pose>
    </frame>

    <frame name='lower_left_wheel_shaft_joint' attached_to='base_link'>
      <pose>-0.75 0.54 0 0 0 0</pose>
    </frame>
    <frame name='lower_left_wheel_shaft' attached_to='lower_left_wheel_shaft_joint'>
      <pose>0 0 0 0 0 0</pose>
    </frame>

    <frame name='lower_right_wheel_shaft_joint' attached_to='base_link'>
      <pose>-0.75 -0.54 0 -3.1415926535895871 0 0</pose>
    </frame>
    <frame name='lower_right_wheel_shaft' attached_to='lower_right_wheel_shaft_joint'>
      <pose>0 0 0 0 0 0</pose>
    </frame>

    <frame name='upper_left_wheel_shaft_joint' attached_to='base_link'>
      <pose>0.75 0.54 0 0 0 0</pose>
    </frame>
    <frame name='upper_left_wheel_shaft' attached_to='upper_left_wheel_shaft_joint'>
      <pose>0 0 0 0 0 0</pose>
    </frame>

    <frame name='upper_right_wheel_shaft_joint' attached_to='base_link'>
      <pose>0.75 -0.54 0 -3.1415926535895871 0 0</pose>
    </frame>
    <frame name='upper_right_wheel_shaft' attached_to='upper_right_wheel_shaft_joint'>
      <pose>0 0 0 0 0 0</pose>
    </frame>

    <frame name='base_link_joint' attached_to='base_footprint'>
      <pose>0 0 0.25 0 0 0</pose>
    </frame>
    <frame name='base_link' attached_to='base_link_joint'>
      <pose>0 0 0 0 0 0</pose>
    </frame>

  </model>
</sdf>
